<?xml version="1.0"?>
<robot name="my_robot">

  <!-- Materials -->
  <material name="grey"><color rgba="0.7 0.7 0.7 1"/></material>
  <material name="green"><color rgba="0 0.6 0 1"/></material>
  <material name="white"><color rgba="1 1 1 1"/></material>
  <material name="gray"><color rgba="0.5 0.5 0.5 1"/></material>

  <!-- base_footprint -->
  <link name="base_footprint"/>

  <!-- Chassis -->
  <link name="base_link">
    <visual>
      <origin xyz="0 0 0.05" rpy="0 0 0"/>
      <geometry><box size="0.56 0.41 0.1"/></geometry>
      <material name="green"/>
    </visual>
    <collision>
      <origin xyz="0 0 0.05" rpy="0 0 0"/>
      <geometry><box size="0.56 0.41 0.1"/></geometry>
    </collision>
    <inertial>
      <origin xyz="0 0 0.1" rpy="0 0 0"/>
      <mass value="10.0"/>
      <inertia ixx="0.1" ixy="0.0" ixz="0.0" iyy="0.1" iyz="0.0" izz="0.1"/>
    </inertial>
  </link>
  <joint name="base_footprint_joint" type="fixed">
    <parent link="base_footprint"/>
    <child link="base_link"/>
    <origin xyz="0 0 0" rpy="0 0 0"/>
  </joint>

  <!-- LiDAR -->
  <link name="lidar_link">
    <visual>
      <origin xyz="0 0 0.1" rpy="0 0 0"/>
      <geometry><cylinder radius="0.05" length="0.03"/></geometry>
      <material name="white"/>
    </visual>
    <collision>
      <origin xyz="0 0 0.1" rpy="0 0 0"/>
      <geometry><cylinder radius="0.05" length="0.03"/></geometry>
    </collision>
    <inertial>
      <origin xyz="0 0 0.1" rpy="0 0 0"/>
      <mass value="0.5"/>
      <inertia ixx="0.001" ixy="0.0" ixz="0.0" iyy="0.001" iyz="0.0" izz="0.001"/>
    </inertial>
  </link>
  <joint name="base_lidar_joint" type="fixed">
    <parent link="base_link"/>
    <child link="lidar_link"/>
    <origin xyz="0 0 0.015" rpy="0 0 0"/>
  </joint>

  <!-- Laser frame -->
  <link name="laser_frame">
    <visual>
      <geometry>
        <cylinder radius="0.025" length="0.05"/>
      </geometry>
      <origin xyz="0 0 0" rpy="0 0 0"/>
      <material name="gray"/>
    </visual>
  </link>
  <joint name="laser_joint" type="fixed">
    <parent link="base_link"/>
    <child link="laser_frame"/>
    <origin xyz="0 0 0.255" rpy="0 0 0"/>
  </joint>

  <!-- Left Wheel -->
  <link name="left_wheel">
    <visual>
      <origin xyz="0 0 0" rpy="1.5708 0 0"/>
      <geometry><cylinder radius="0.05" length="0.03"/></geometry>
      <material name="grey"/>
    </visual>
    <collision>
      <origin xyz="0 0 0" rpy="1.5708 0 0"/>
      <geometry><cylinder radius="0.05" length="0.03"/></geometry>
    </collision>
    <inertial>
      <origin xyz="0 0 0" rpy="0 0 0"/>
      <mass value="0.5"/>
      <inertia ixx="0.001" ixy="0.0" ixz="0.0" iyy="0.001" iyz="0.0" izz="0.001"/>
    </inertial>
  </link>
  <joint name="base_left_wheel_joint" type="continuous">
    <parent link="base_link"/>
    <child link="left_wheel"/>
    <origin xyz="0 -0.22 0" rpy="0 0 0"/>
    <axis xyz="0 1 0"/>
  </joint>

  <!-- Right Wheel -->
  <link name="right_wheel">
    <visual>
      <origin xyz="0 0 0" rpy="1.5708 0 0"/>
      <geometry><cylinder radius="0.05" length="0.03"/></geometry>
      <material name="grey"/>
    </visual>
    <collision>
      <origin xyz="0 0 0" rpy="1.5708 0 0"/>
      <geometry><cylinder radius="0.05" length="0.03"/></geometry>
    </collision>
    <inertial>
      <origin xyz="0 0 0" rpy="0 0 0"/>
      <mass value="0.5"/>
      <inertia ixx="0.001" ixy="0.0" ixz="0.0" iyy="0.001" iyz="0.0" izz="0.001"/>
    </inertial>
  </link>
  <joint name="base_right_wheel_joint" type="continuous">
    <parent link="base_link"/>
    <child link="right_wheel"/>
    <origin xyz="0 0.22 0" rpy="0 0 0"/>
    <axis xyz="0 1 0"/>
  </joint>

  <!-- Caster Wheels -->
  <!-- caster_1 -->
  <link name="caster_1">
    <visual>
      <origin xyz="0 0 0" rpy="0 0 0"/>
      <geometry><sphere radius="0.025"/></geometry>
      <material name="grey"/>
    </visual>
    <collision>
      <origin xyz="0 0 0"/>
      <geometry><sphere radius="0.025"/></geometry>
    </collision>
    <inertial>
      <mass value="0.1"/>
      <origin xyz="0 0 0"/>
      <inertia ixx="0.0001" iyy="0.0001" izz="0.0001" ixy="0.0" ixz="0.0" iyz="0.0"/>
    </inertial>
  </link>
  <joint name="caster_1_joint" type="fixed">
    <parent link="base_link"/>
    <child link="caster_1"/>
    <origin xyz="0.25 0.15 -0.0225" rpy="0 0 0"/>
  </joint>

  <!-- caster_2 -->
  <link name="caster_2">
    <visual>
      <origin xyz="0 0 0" rpy="0 0 0"/>
      <geometry><sphere radius="0.025"/></geometry>
      <material name="grey"/>
    </visual>
    <collision>
      <origin xyz="0 0 0"/>
      <geometry><sphere radius="0.025"/></geometry>
    </collision>
    <inertial>
      <mass value="0.1"/>
      <origin xyz="0 0 0"/>
      <inertia ixx="0.0001" iyy="0.0001" izz="0.0001" ixy="0.0" ixz="0.0" iyz="0.0"/>
    </inertial>
  </link>
  <joint name="caster_2_joint" type="fixed">
    <parent link="base_link"/>
    <child link="caster_2"/>
    <origin xyz="0.25 -0.15 -0.0225" rpy="0 0 0"/>
  </joint>

  <!-- caster_3 -->
  <link name="caster_3">
    <visual>
      <origin xyz="0 0 0" rpy="0 0 0"/>
      <geometry><sphere radius="0.025"/></geometry>
      <material name="grey"/>
    </visual>
    <collision>
      <origin xyz="0 0 0"/>
      <geometry><sphere radius="0.025"/></geometry>
    </collision>
    <inertial>
      <mass value="0.1"/>
      <origin xyz="0 0 0"/>
      <inertia ixx="0.0001" iyy="0.0001" izz="0.0001" ixy="0.0" ixz="0.0" iyz="0.0"/>
    </inertial>
  </link>
  <joint name="caster_3_joint" type="fixed">
    <parent link="base_link"/>
    <child link="caster_3"/>
    <origin xyz="-0.25 0.15 -0.0225" rpy="0 0 0"/>
  </joint>

  <!-- caster_4 -->
  <link name="caster_4">
    <visual>
      <origin xyz="0 0 0" rpy="0 0 0"/>
      <geometry><sphere radius="0.025"/></geometry>
      <material name="grey"/>
    </visual>
    <collision>
      <origin xyz="0 0 0"/>
      <geometry><sphere radius="0.025"/></geometry>
    </collision>
    <inertial>
      <mass value="0.1"/>
      <origin xyz="0 0 0"/>
      <inertia ixx="0.0001" iyy="0.0001" izz="0.0001" ixy="0.0" ixz="0.0" iyz="0.0"/>
    </inertial>
  </link>
  <joint name="caster_4_joint" type="fixed">
    <parent link="base_link"/>
    <child link="caster_4"/>
    <origin xyz="-0.25 -0.15 -0.0225" rpy="0 0 0"/>
  </joint>

</robot>

